Workbook
Name Date: 'Kupeic Test'!$A$1

Sheet Merged_data
A1: Date | B1: AAPL_Close | C1: XAUUSD_Close | D1: BTCUSD_Close
A2: 45589 | B2: 230.064 | C2: 2735.985 | D2: 68306.4
A3: 45590 | B3: 230.902 | C3: 2742.535 | D3: 66786.4
A4: 45593 | B4: 232.887 | C4: 2742.225 | D4: 69912.9
A5: 45594 | B5: 233.157 | C5: 2774.68 | D5: 72616.8
A6: 45595 | B6: 229.595 | C6: 2787.59 | D6: 72374.6
A7: 45596 | B7: 225.414 | C7: 2746.205 | D7: 70371.9
A8: 45597 | B8: 222.42 | C8: 2736.515 | D8: 69192.6
A9: 45600 | B9: 221.522 | C9: 2736.685 | D9: 67885.4
A10: 45601 | B10: 222.959 | C10: 2743.995 | D10: 69586
A11: 45602 | B11: 222.231 | C11: 2659.055 | D11: 75684.1
A12: 45603 | B12: 226.98 | C12: 2706.51 | D12: 75908.2
A13: 45604 | B13: 226.711 | C13: 2685.17 | D13: 76677.7
... A252: 45954 | B252: 261.3 | C252: 4120.845 | D252: 110010

Sheet Calculation
A1: {=Merged_data[[#All],[Date]]} -> Date | B1: {=Merged_data[[#All],[AAPL_Close]]} -> AAPL_Close | C1: Date | D1: Apple | E1: {=Merged_data[[#All],[XAUUSD_Close]]} -> XAUUSD_Close | F1: XAUUSD | G1: {=Merged_data[[#All],[BTCUSD_Close]]} -> BTCUSD_Close | H1: BTCUSD | I1: {='Kupeic Test'!E1:E251} -> Portfolio_return | J1: Portfolio | AB1: Number of Breaches
A2: 45589 | B2: 230.064 | C2: =TEXT(A2, "mmm yyyy") -> Oct 2024 | D2: =B2/$B$2*100 -> 100 | E2: 2735.985 | F2: =E2/$E$2*100 -> 100 | G2: 68306.4 | H2: =G2/$G$2*100 -> 100 | I2: 0 | J2: 100 | S2: {='Kupeic Test'!J7:L10} -> VaR Methods | T2: 99% CI | U2: 95% CI | W2: {='Kupeic Test'!J1:M3} -> Stocks | X2: BTCUSD | Y2: XAUUSD | Z2: AAPL | AB2: Methods | AC2: Days | AD2: {=AB2:AB5} -> Methods | AE2: ='Kupeic Test'!J18 -> p value | AF2: Result
A3: 45590 | B3: 230.902 | C3: =TEXT(A3, "mmm yyyy") -> Oct 2024 | D3: =B3/$B$2*100 -> 100.36425 | E3: 2742.535 | F3: =E3/$E$2*100 -> 100.2394 | G3: 66786.4 | H3: =G3/$G$2*100 -> 97.774733 | I3: -0.004625455 | J3: =J2 * (1 + I3) -> 99.537455 | S3: Historical | T3: 32536.521 | U3: 17449.262 | W3: Weights | X3: 0.3 | Y3: 0.4 | Z3: 0.3 | AB3: ='Kupeic Test'!M12 -> Monte Carlo | AC3: ='Kupeic Test'!M14 -> 3 | AD3: Monte Carlo | AE3: ='Kupeic Test'!M18 -> 0.75299278 | AF3: ='Kupeic Test'!M19 -> Reliable
A4: 45593 | B4: 232.887 | C4: =TEXT(A4, "mmm yyyy") -> Oct 2024 | D4: =B4/$B$2*100 -> 101.22705 | E4: 2742.225 | F4: =E4/$E$2*100 -> 100.22807 | G4: 69912.9 | H4: =G4/$G$2*100 -> 102.3519 | I4: 0.016577829 | J4: =J3 * (1 + I4) -> 101.18757 | S4: Parametric | T4: 27930.257 | U4: 19286.185 | W4: Stock Value | X4: 300000 | Y4: 400000 | Z4: 300000 | AB4: ='Kupeic Test'!K12 -> Historical | AC4: ='Kupeic Test'!K14 -> 6 | AD4: Historical | AE4: ='Kupeic Test'!K18 -> 0.058340692 | AF4: ='Kupeic Test'!K19 -> Reliable
A5: 45594 | B5: 233.157 | C5: =TEXT(A5, "mmm yyyy") -> Oct 2024 | D5: =B5/$B$2*100 -> 101.34441 | E5: 2774.68 | F5: =E5/$E$2*100 -> 101.4143 | G5: 72616.8 | H5: =G5/$G$2*100 -> 106.31039 | I5: 0.0166845 | J5: =J4 * (1 + I5) -> 102.87583 | S5: Monte Carlo | T5: 36995.535 | U5: 28559.017 | AB5: ='Kupeic Test'!L12 -> Parametric | AC5: ='Kupeic Test'!L14 -> 8 | AD5: Parametric | AE5: ='Kupeic Test'!L18 -> 0.0052867904 | AF5: ='Kupeic Test'!L19 -> Not Reliable
A6: 45595 | B6: 229.595 | C6: =TEXT(A6, "mmm yyyy") -> Oct 2024 | D6: =B6/$B$2*100 -> 99.796144 | E6: 2787.59 | F6: =E6/$E$2*100 -> 101.88616 | G6: 72374.6 | H6: =G6/$G$2*100 -> 105.95581 | I6: -0.0037226572 | J6: =J5 * (1 + I6) -> 102.49286
A7: 45596 | B7: 225.414 | C7: =TEXT(A7, "mmm yyyy") -> Oct 2024 | D7: =B7/$B$2*100 -> 97.978823 | E7: 2746.205 | F7: =E7/$E$2*100 -> 100.37354 | G7: 70371.9 | H7: =G7/$G$2*100 -> 103.02387 | I7: -0.019702954 | J7: =J6 * (1 + I7) -> 100.47345
A8: 45597 | B8: 222.42 | C8: =TEXT(A8, "mmm yyyy") -> Nov 2024 | D8: =B8/$B$2*100 -> 96.677446 | E8: 2736.515 | F8: =E8/$E$2*100 -> 100.01937 | G8: 69192.6 | H8: =G8/$G$2*100 -> 101.29739 | I8: -0.010423503 | J8: =J7 * (1 + I8) -> 99.426164
A9: 45600 | B9: 221.522 | C9: =TEXT(A9, "mmm yyyy") -> Nov 2024 | D9: =B9/$B$2*100 -> 96.28712 | E9: 2736.685 | F9: =E9/$E$2*100 -> 100.02558 | G9: 67885.4 | H9: =G9/$G$2*100 -> 99.38366 | I9: -0.006854031 | J9: =J8 * (1 + I9) -> 98.744694
A10: 45601 | B10: 222.959 | C10: =TEXT(A10, "mmm yyyy") -> Nov 2024 | D10: =B10/$B$2*100 -> 96.911729 | E10: 2743.995 | F10: =E10/$E$2*100 -> 100.29276 | G10: 69586 | H10: =G10/$G$2*100 -> 101.87332 | I10: 0.010529841 | J10: =J9 * (1 + I10) -> 99.78446
A11: 45602 | B11: 222.231 | C11: =TEXT(A11, "mmm yyyy") -> Nov 2024 | D11: =B11/$B$2*100 -> 96.595295 | E11: 2659.055 | F11: =E11/$E$2*100 -> 97.188216 | G11: 75684.1 | H11: =G11/$G$2*100 -> 110.80089 | I11: 0.012928703 | J11: =J10 * (1 + I11) -> 101.07454
A12: 45603 | B12: 226.98 | C12: =TEXT(A12, "mmm yyyy") -> Nov 2024 | D12: =B12/$B$2*100 -> 98.659503 | E12: 2706.51 | F12: =E12/$E$2*100 -> 98.922691 | G12: 75908.2 | H12: =G12/$G$2*100 -> 111.12897 | I12: 0.014437821 | J12: =J11 * (1 + I12) -> 102.53384
A13: 45604 | B13: 226.711 | C13: =TEXT(A13, "mmm yyyy") -> Nov 2024 | D13: =B13/$B$2*100 -> 98.542579 | E13: 2685.17 | F13: =E13/$E$2*100 -> 98.142716 | G13: 76677.7 | H13: =G13/$G$2*100 -> 112.25551 | I13: -0.00046824165 | J13: =J12 * (1 + I13) -> 102.48583
A14: 45607 | B14: 223.984 | C14: =TEXT(A14, "mmm yyyy") -> Nov 2024 | D14: =B14/$B$2*100 -> 97.357257 | E14: 2619.54 | F14: =E14/$E$2*100 -> 95.743946 | G14: 88143.7 | H14: =G14/$G$2*100 -> 129.04164 | I14: 0.031475279 | J14: =J13 * (1 + I14) -> 105.7116
A15: 45608 | B15: 223.984 | C15: =TEXT(A15, "mmm yyyy") -> Nov 2024 | D15: =B15/$B$2*100 -> 97.357257 | E15: 2598.275 | F15: =E15/$E$2*100 -> 94.966712 | G15: 88638.3 | H15: =G15/$G$2*100 -> 129.76573 | I15: -0.0015637475 | J15: =J14 * (1 + I15) -> 105.54629
A16: 45609 | B16: 224.873 | C16: =TEXT(A16, "mmm yyyy") -> Nov 2024 | D16: =B16/$B$2*100 -> 97.743671 | E16: 2572.935 | F16: =E16/$E$2*100 -> 94.040538 | G16: 89785.1 | H16: =G16/$G$2*100 -> 131.44464 | I16: 0.0011710524 | J16: =J15 * (1 + I16) -> 105.66989
A17: 45610 | B17: 227.969 | C17: =TEXT(A17, "mmm yyyy") -> Nov 2024 | D17: =B17/$B$2*100 -> 99.089384 | E17: 2565.05 | F17: =E17/$E$2*100 -> 93.752341 | G17: 87718.5 | H17: =G17/$G$2*100 -> 128.41915 | I17: -0.0040006607 | J17: =J16 * (1 + I17) -> 105.24714
... A251: 45953 | B251: 259.58 | C251: =TEXT(A251, "mmm yyyy") -> Oct 2025 | D251: =B251/$B$2*100 -> 112.82947 | E251: 4126.67 | F251: =E251/$E$2*100 -> 150.82941 | G251: 109591 | H251: =G251/$G$2*100 -> 160.44031 | I251: 0.010679256 | J251: =J250 * (1 + I251) -> 145.28113
A252: 45954 | B252: 261.3 | E252: 4120.845 | G252: 110010

Sheet Historical
A1: BTCUSD_return | B1: XAUSSD_return | C1: AAPL_return | D1: Portfolio_return | E1: Asc_prt_ret | F1: Ranks | H1: Stocks | I1: BTC | J1: Gold | K1: AAPL
H2: Weights | I2: 0.3 | J2: 0.4 | K2: 0.3
A3: =IFERROR(Merged_data[[#This Row],[BTCUSD_Close]]/Merged_data!D2-1,"") -> -0.022252673 | B3: =IFERROR(Merged_data[[#This Row],[XAUUSD_Close]]/Merged_data!C2-1, "") -> 0.002394019 | C3: =IFERROR(Merged_data[[#This Row],[AAPL_Close]]/Merged_data!B2-1,"") -> 0.0036424647 | D3: =SUMPRODUCT(A3:C3,$I$2:$K$2) -> -0.004625455 | E3: {=_xlfn._xlws.SORT(D3:D251)} -> -0.046119973 | F3: 1 | H3: Stock Value | I3: 300000 | J3: 400000 | K3: 300000
A4: =IFERROR(Merged_data[[#This Row],[BTCUSD_Close]]/Merged_data!D3-1,"") -> 0.046813423 | B4: =IFERROR(Merged_data[[#This Row],[XAUUSD_Close]]/Merged_data!C3-1, "") -> -0.00011303411 | C4: =IFERROR(Merged_data[[#This Row],[AAPL_Close]]/Merged_data!B3-1,"") -> 0.0085967207 | D4: =SUMPRODUCT(A4:C4,$I$2:$K$2) -> 0.016577829 | E4: -0.037838509 | F4: 2
A5: =IFERROR(Merged_data[[#This Row],[BTCUSD_Close]]/Merged_data!D4-1,"") -> 0.038675266 | B5: =IFERROR(Merged_data[[#This Row],[XAUUSD_Close]]/Merged_data!C4-1, "") -> 0.01183528 | C5: =IFERROR(Merged_data[[#This Row],[AAPL_Close]]/Merged_data!B4-1,"") -> 0.0011593605 | D5: =SUMPRODUCT(A5:C5,$I$2:$K$2) -> 0.0166845 | E5: -0.035246479 | F5: 3
A6: =IFERROR(Merged_data[[#This Row],[BTCUSD_Close]]/Merged_data!D5-1,"") -> -0.0033353163 | B6: =IFERROR(Merged_data[[#This Row],[XAUUSD_Close]]/Merged_data!C5-1, "") -> 0.0046527888 | C6: =IFERROR(Merged_data[[#This Row],[AAPL_Close]]/Merged_data!B5-1,"") -> -0.01527726 | D6: =SUMPRODUCT(A6:C6,$I$2:$K$2) -> -0.0037226572 | E6: -0.029480611 | F6: 4 | H6: Portfolio Value | I6: ='Kupeic Test'!K5 -> 1000000
A7: =IFERROR(Merged_data[[#This Row],[BTCUSD_Close]]/Merged_data!D6-1,"") -> -0.02767131 | B7: =IFERROR(Merged_data[[#This Row],[XAUUSD_Close]]/Merged_data!C6-1, "") -> -0.014846157 | C7: =IFERROR(Merged_data[[#This Row],[AAPL_Close]]/Merged_data!B6-1,"") -> -0.018210327 | D7: =SUMPRODUCT(A7:C7,$I$2:$K$2) -> -0.019702954 | E7: -0.027108902 | F7: 5
A8: =IFERROR(Merged_data[[#This Row],[BTCUSD_Close]]/Merged_data!D7-1,"") -> -0.016758109 | B8: =IFERROR(Merged_data[[#This Row],[XAUUSD_Close]]/Merged_data!C7-1, "") -> -0.0035285057 | C8: =IFERROR(Merged_data[[#This Row],[AAPL_Close]]/Merged_data!B7-1,"") -> -0.013282227 | D8: =SUMPRODUCT(A8:C8,$I$2:$K$2) -> -0.010423503 | E8: -0.023243007 | F8: 6
A9: =IFERROR(Merged_data[[#This Row],[BTCUSD_Close]]/Merged_data!D8-1,"") -> -0.018892194 | B9: =IFERROR(Merged_data[[#This Row],[XAUUSD_Close]]/Merged_data!C8-1, "") -> 6.2122809e-05 | C9: =IFERROR(Merged_data[[#This Row],[AAPL_Close]]/Merged_data!B8-1,"") -> -0.0040374067 | D9: =SUMPRODUCT(A9:C9,$I$2:$K$2) -> -0.006854031 | E9: -0.023137174 | F9: 7
A10: =IFERROR(Merged_data[[#This Row],[BTCUSD_Close]]/Merged_data!D9-1,"") -> 0.025051042 | B10: =IFERROR(Merged_data[[#This Row],[XAUUSD_Close]]/Merged_data!C9-1, "") -> 0.0026711149 | C10: =IFERROR(Merged_data[[#This Row],[AAPL_Close]]/Merged_data!B9-1,"") -> 0.0064869403 | D10: =SUMPRODUCT(A10:C10,$I$2:$K$2) -> 0.010529841 | E10: -0.022584544 | F10: 8 | H10: VaR Using Historical Simulation Method
A11: =IFERROR(Merged_data[[#This Row],[BTCUSD_Close]]/Merged_data!D10-1,"") -> 0.087634007 | B11: =IFERROR(Merged_data[[#This Row],[XAUUSD_Close]]/Merged_data!C10-1, "") -> -0.030954867 | C11: =IFERROR(Merged_data[[#This Row],[AAPL_Close]]/Merged_data!B10-1,"") -> -0.0032651743 | D11: =SUMPRODUCT(A11:C11,$I$2:$K$2) -> 0.012928703 | E11: -0.019749635 | F11: 9 | H11: Total no. of days | I11: =COUNT(F3:F251) -> 249 | J11: =COUNT(F3:F251) -> 249
A12: =IFERROR(Merged_data[[#This Row],[BTCUSD_Close]]/Merged_data!D11-1,"") -> 0.0029609918 | B12: =IFERROR(Merged_data[[#This Row],[XAUUSD_Close]]/Merged_data!C11-1, "") -> 0.017846566 | C12: =IFERROR(Merged_data[[#This Row],[AAPL_Close]]/Merged_data!B11-1,"") -> 0.021369656 | D12: =SUMPRODUCT(A12:C12,$I$2:$K$2) -> 0.014437821 | E12: -0.019702954 | F12: 10 | H12: Confidence Level | I12: 0.99 | J12: 0.95
A13: =IFERROR(Merged_data[[#This Row],[BTCUSD_Close]]/Merged_data!D12-1,"") -> 0.010137245 | B13: =IFERROR(Merged_data[[#This Row],[XAUUSD_Close]]/Merged_data!C12-1, "") -> -0.0078846928 | C13: =IFERROR(Merged_data[[#This Row],[AAPL_Close]]/Merged_data!B12-1,"") -> -0.0011851264 | D13: =SUMPRODUCT(A13:C13,$I$2:$K$2) -> -0.00046824165 | E13: -0.018957131 | F13: 11 | H13: Alpha | I13: 0.01 | J13: 0.05
A14: =IFERROR(Merged_data[[#This Row],[BTCUSD_Close]]/Merged_data!D13-1,"") -> 0.149535 | B14: =IFERROR(Merged_data[[#This Row],[XAUUSD_Close]]/Merged_data!C13-1, "") -> -0.024441655 | C14: =IFERROR(Merged_data[[#This Row],[AAPL_Close]]/Merged_data!B13-1,"") -> -0.01202853 | D14: =SUMPRODUCT(A14:C14,$I$2:$K$2) -> 0.031475279 | E14: -0.018708267 | F14: 12 | H14: Return rate | I14: =_xlfn.PERCENTILE.INC(D3:D250,0.01) -> -0.032536521 | J14: =_xlfn.PERCENTILE.INC(D3:D250,0.05) -> -0.017449262
A15: =IFERROR(Merged_data[[#This Row],[BTCUSD_Close]]/Merged_data!D14-1,"") -> 0.0056112916 | B15: =IFERROR(Merged_data[[#This Row],[XAUUSD_Close]]/Merged_data!C14-1, "") -> -0.0081178375 | C15: =IFERROR(Merged_data[[#This Row],[AAPL_Close]]/Merged_data!B14-1,"") -> 0 | D15: =SUMPRODUCT(A15:C15,$I$2:$K$2) -> -0.0015637475 | E15: -0.01750616 | F15: 13 | H15: Portfolio Value | I15: =I6 -> 1000000 | J15: =I6 -> 1000000
A16: =IFERROR(Merged_data[[#This Row],[BTCUSD_Close]]/Merged_data!D15-1,"") -> 0.012937974 | B16: =IFERROR(Merged_data[[#This Row],[XAUUSD_Close]]/Merged_data!C15-1, "") -> -0.0097526243 | C16: =IFERROR(Merged_data[[#This Row],[AAPL_Close]]/Merged_data!B15-1,"") -> 0.0039690335 | D16: =SUMPRODUCT(A16:C16,$I$2:$K$2) -> 0.0011710524 | E16: -0.017343596 | F16: 14 | H16: 1 Day VaR | I16: =ABS(I15*I14) -> 32536.521 | J16: =ABS(J15*J14) -> 17449.262
A17: =IFERROR(Merged_data[[#This Row],[BTCUSD_Close]]/Merged_data!D16-1,"") -> -0.023017182 | B17: =IFERROR(Merged_data[[#This Row],[XAUUSD_Close]]/Merged_data!C16-1, "") -> -0.0030645935 | C17: =IFERROR(Merged_data[[#This Row],[AAPL_Close]]/Merged_data!B16-1,"") -> 0.013767771 | D17: =SUMPRODUCT(A17:C17,$I$2:$K$2) -> -0.0040006607 | E17: -0.016383094 | F17: 15
A18: =IFERROR(Merged_data[[#This Row],[BTCUSD_Close]]/Merged_data!D17-1,"") -> 0.04063909 | B18: =IFERROR(Merged_data[[#This Row],[XAUUSD_Close]]/Merged_data!C17-1, "") -> -0.0010604082 | C18: =IFERROR(Merged_data[[#This Row],[AAPL_Close]]/Merged_data!B17-1,"") -> -0.014107181 | D18: =SUMPRODUCT(A18:C18,$I$2:$K$2) -> 0.0075354093 | E18: -0.015938733 | F18: 16
A19: =IFERROR(Merged_data[[#This Row],[BTCUSD_Close]]/Merged_data!D18-1,"") -> -0.00048311137 | B19: =IFERROR(Merged_data[[#This Row],[XAUUSD_Close]]/Merged_data!C18-1, "") -> 0.019333966 | C19: =IFERROR(Merged_data[[#This Row],[AAPL_Close]]/Merged_data!B18-1,"") -> 0.013423625 | D19: =SUMPRODUCT(A19:C19,$I$2:$K$2) -> 0.01161574 | E19: -0.015353021 | F19: 17
A20: =IFERROR(Merged_data[[#This Row],[BTCUSD_Close]]/Merged_data!D19-1,"") -> 0.0077039255 | B20: =IFERROR(Merged_data[[#This Row],[XAUUSD_Close]]/Merged_data!C19-1, "") -> 0.0078085816 | C20: =IFERROR(Merged_data[[#This Row],[AAPL_Close]]/Merged_data!B19-1,"") -> 0.001137112 | D20: =SUMPRODUCT(A20:C20,$I$2:$K$2) -> 0.0057757439 | E20: -0.015209476 | F20: 18
A21: =IFERROR(Merged_data[[#This Row],[BTCUSD_Close]]/Merged_data!D20-1,"") -> 0.024838458 | B21: =IFERROR(Merged_data[[#This Row],[XAUUSD_Close]]/Merged_data!C20-1, "") -> 0.0068382173 | C21: =IFERROR(Merged_data[[#This Row],[AAPL_Close]]/Merged_data!B20-1,"") -> 0.0031531077 | D21: =SUMPRODUCT(A21:C21,$I$2:$K$2) -> 0.011132757 | E21: -0.014822566 | F21: 19
A22: =IFERROR(Merged_data[[#This Row],[BTCUSD_Close]]/Merged_data!D21-1,"") -> 0.044587576 | B22: =IFERROR(Merged_data[[#This Row],[XAUUSD_Close]]/Merged_data!C21-1, "") -> 0.0073200227 | C22: =IFERROR(Merged_data[[#This Row],[AAPL_Close]]/Merged_data!B21-1,"") -> -0.0020940074 | D22: =SUMPRODUCT(A22:C22,$I$2:$K$2) -> 0.01567608 | E22: -0.01440382 | F22: 20
A23: =IFERROR(Merged_data[[#This Row],[BTCUSD_Close]]/Merged_data!D22-1,"") -> 0.0077468502 | B23: =IFERROR(Merged_data[[#This Row],[XAUUSD_Close]]/Merged_data!C22-1, "") -> 0.013591593 | C23: =IFERROR(Merged_data[[#This Row],[AAPL_Close]]/Merged_data!B22-1,"") -> 0.0059096943 | D23: =SUMPRODUCT(A23:C23,$I$2:$K$2) -> 0.0095336005 | E23: -0.013683646 | F23: 21
A24: =IFERROR(Merged_data[[#This Row],[BTCUSD_Close]]/Merged_data!D23-1,"") -> -0.048555494 | B24: =IFERROR(Merged_data[[#This Row],[XAUUSD_Close]]/Merged_data!C23-1, "") -> -0.029830559 | C24: =IFERROR(Merged_data[[#This Row],[AAPL_Close]]/Merged_data!B23-1,"") -> 0.013047758 | D24: =SUMPRODUCT(A24:C24,$I$2:$K$2) -> -0.022584544 | E24: -0.011879172 | F24: 22
A25: =IFERROR(Merged_data[[#This Row],[BTCUSD_Close]]/Merged_data!D24-1,"") -> -0.027746166 | B25: =IFERROR(Merged_data[[#This Row],[XAUUSD_Close]]/Merged_data!C24-1, "") -> 0.0030454474 | C25: =IFERROR(Merged_data[[#This Row],[AAPL_Close]]/Merged_data!B24-1,"") -> 0.0094061406 | D25: =SUMPRODUCT(A25:C25,$I$2:$K$2) -> -0.0042838286 | E25: -0.011549907 | F25: 23
A26: =IFERROR(Merged_data[[#This Row],[BTCUSD_Close]]/Merged_data!D25-1,"") -> 0.047709714 | B26: =IFERROR(Merged_data[[#This Row],[XAUUSD_Close]]/Merged_data!C25-1, "") -> 0.0010329539 | C26: =IFERROR(Merged_data[[#This Row],[AAPL_Close]]/Merged_data!B25-1,"") -> -0.00055365798 | D26: =SUMPRODUCT(A26:C26,$I$2:$K$2) -> 0.014559998 | E26: -0.011440874 | F26: 24
A27: =IFERROR(Merged_data[[#This Row],[BTCUSD_Close]]/Merged_data!D26-1,"") -> 0.012912387 | B27: =IFERROR(Merged_data[[#This Row],[XAUUSD_Close]]/Merged_data!C26-1, "") -> 0.0055046672 | C27: =IFERROR(Merged_data[[#This Row],[AAPL_Close]]/Merged_data!B26-1,"") -> 0.010214256 | D27: =SUMPRODUCT(A27:C27,$I$2:$K$2) -> 0.0091398598 | E27: -0.01104456 | F27: 25
A28: =IFERROR(Merged_data[[#This Row],[BTCUSD_Close]]/Merged_data!D27-1,"") -> -0.020207694 | B28: =IFERROR(Merged_data[[#This Row],[XAUUSD_Close]]/Merged_data!C27-1, "") -> -0.0042992618 | C28: =IFERROR(Merged_data[[#This Row],[AAPL_Close]]/Merged_data!B27-1,"") -> 0.0095246532 | D28: =SUMPRODUCT(A28:C28,$I$2:$K$2) -> -0.0049246171 | E28: -0.010924468 | F28: 26
... A251: =IFERROR(Merged_data[[#This Row],[BTCUSD_Close]]/Merged_data!D250-1,"") -> 0.022008561 | B251: =IFERROR(Merged_data[[#This Row],[XAUUSD_Close]]/Merged_data!C250-1, "") -> 0.0069125548 | C251: =IFERROR(Merged_data[[#This Row],[AAPL_Close]]/Merged_data!B250-1,"") -> 0.004372219 | D251: =SUMPRODUCT(A251:C251,$I$2:$K$2) -> 0.010679256 | E251: 0.083799714 | F251: 249

Sheet Parametric
A1: BTCUSD_return | B1: XAUSSD_return | C1: AAPL_return | D1: Portfolio_return | H1: Stocks | I1: BTC | J1: Gold | K1: AAPL
H2: Weights | I2: 0.3 | J2: 0.4 | K2: 0.3
A3: =IFERROR(Merged_data[[#This Row],[BTCUSD_Close]]/Merged_data!D2-1,"") -> -0.022252673 | B3: =IFERROR(Merged_data[[#This Row],[XAUUSD_Close]]/Merged_data!C2-1, "") -> 0.002394019 | C3: =IFERROR(Merged_data[[#This Row],[AAPL_Close]]/Merged_data!B2-1,"") -> 0.0036424647 | D3: =SUMPRODUCT(A3:C3,$I$2:$K$2) -> -0.004625455 | H3: Stock Value | I3: 300000 | J3: 400000 | K3: 300000
A4: =IFERROR(Merged_data[[#This Row],[BTCUSD_Close]]/Merged_data!D3-1,"") -> 0.046813423 | B4: =IFERROR(Merged_data[[#This Row],[XAUUSD_Close]]/Merged_data!C3-1, "") -> -0.00011303411 | C4: =IFERROR(Merged_data[[#This Row],[AAPL_Close]]/Merged_data!B3-1,"") -> 0.0085967207 | D4: =SUMPRODUCT(A4:C4,$I$2:$K$2) -> 0.016577829
A5: =IFERROR(Merged_data[[#This Row],[BTCUSD_Close]]/Merged_data!D4-1,"") -> 0.038675266 | B5: =IFERROR(Merged_data[[#This Row],[XAUUSD_Close]]/Merged_data!C4-1, "") -> 0.01183528 | C5: =IFERROR(Merged_data[[#This Row],[AAPL_Close]]/Merged_data!B4-1,"") -> 0.0011593605 | D5: =SUMPRODUCT(A5:C5,$I$2:$K$2) -> 0.0166845 | H5: Portfolio Mean Return | I5: =AVERAGE(D3:D251) -> 0.0015771349
A6: =IFERROR(Merged_data[[#This Row],[BTCUSD_Close]]/Merged_data!D5-1,"") -> -0.0033353163 | B6: =IFERROR(Merged_data[[#This Row],[XAUUSD_Close]]/Merged_data!C5-1, "") -> 0.0046527888 | C6: =IFERROR(Merged_data[[#This Row],[AAPL_Close]]/Merged_data!B5-1,"") -> -0.01527726 | D6: =SUMPRODUCT(A6:C6,$I$2:$K$2) -> -0.0037226572
A7: =IFERROR(Merged_data[[#This Row],[BTCUSD_Close]]/Merged_data!D6-1,"") -> -0.02767131 | B7: =IFERROR(Merged_data[[#This Row],[XAUUSD_Close]]/Merged_data!C6-1, "") -> -0.014846157 | C7: =IFERROR(Merged_data[[#This Row],[AAPL_Close]]/Merged_data!B6-1,"") -> -0.018210327 | D7: =SUMPRODUCT(A7:C7,$I$2:$K$2) -> -0.019702954 | H7: Covariance | I7: BTC | J7: Gold | K7: AAPL
A8: =IFERROR(Merged_data[[#This Row],[BTCUSD_Close]]/Merged_data!D7-1,"") -> -0.016758109 | B8: =IFERROR(Merged_data[[#This Row],[XAUUSD_Close]]/Merged_data!C7-1, "") -> -0.0035285057 | C8: =IFERROR(Merged_data[[#This Row],[AAPL_Close]]/Merged_data!B7-1,"") -> -0.013282227 | D8: =SUMPRODUCT(A8:C8,$I$2:$K$2) -> -0.010423503 | H8: BTC | I8: =VARP(Parametric!$A$3:$A$251) -> 0.00073196879 | J8: =I9 -> 1.6254597e-05 | K8: =I10 -> 0.00015794059
A9: =IFERROR(Merged_data[[#This Row],[BTCUSD_Close]]/Merged_data!D8-1,"") -> -0.018892194 | B9: =IFERROR(Merged_data[[#This Row],[XAUUSD_Close]]/Merged_data!C8-1, "") -> 6.2122809e-05 | C9: =IFERROR(Merged_data[[#This Row],[AAPL_Close]]/Merged_data!B8-1,"") -> -0.0040374067 | D9: =SUMPRODUCT(A9:C9,$I$2:$K$2) -> -0.006854031 | H9: Gold | I9: 1.6254597e-05 | J9: =VARP(Parametric!$B$3:$B$251) -> 0.00014819566 | K9: =J10 -> 3.7105672e-06
A10: =IFERROR(Merged_data[[#This Row],[BTCUSD_Close]]/Merged_data!D9-1,"") -> 0.025051042 | B10: =IFERROR(Merged_data[[#This Row],[XAUUSD_Close]]/Merged_data!C9-1, "") -> 0.0026711149 | C10: =IFERROR(Merged_data[[#This Row],[AAPL_Close]]/Merged_data!B9-1,"") -> 0.0064869403 | D10: =SUMPRODUCT(A10:C10,$I$2:$K$2) -> 0.010529841 | H10: AAPL | I10: 0.00015794059 | J10: 3.7105672e-06 | K10: =VARP(Parametric!$C$3:$C$251) -> 0.0004230485
A11: =IFERROR(Merged_data[[#This Row],[BTCUSD_Close]]/Merged_data!D10-1,"") -> 0.087634007 | B11: =IFERROR(Merged_data[[#This Row],[XAUUSD_Close]]/Merged_data!C10-1, "") -> -0.030954867 | C11: =IFERROR(Merged_data[[#This Row],[AAPL_Close]]/Merged_data!B10-1,"") -> -0.0032651743 | D11: =SUMPRODUCT(A11:C11,$I$2:$K$2) -> 0.012928703
A12: =IFERROR(Merged_data[[#This Row],[BTCUSD_Close]]/Merged_data!D11-1,"") -> 0.0029609918 | B12: =IFERROR(Merged_data[[#This Row],[XAUUSD_Close]]/Merged_data!C11-1, "") -> 0.017846566 | C12: =IFERROR(Merged_data[[#This Row],[AAPL_Close]]/Merged_data!B11-1,"") -> 0.021369656 | D12: =SUMPRODUCT(A12:C12,$I$2:$K$2) -> 0.014437821 | H12: Portfilio Standard Deviation | I12: {=SQRT(MMULT(MMULT($I$2:$K$2,I8:K10),TRANSPOSE($I$2:$K$2)))} -> 0.012683998
A13: =IFERROR(Merged_data[[#This Row],[BTCUSD_Close]]/Merged_data!D12-1,"") -> 0.010137245 | B13: =IFERROR(Merged_data[[#This Row],[XAUUSD_Close]]/Merged_data!C12-1, "") -> -0.0078846928 | C13: =IFERROR(Merged_data[[#This Row],[AAPL_Close]]/Merged_data!B12-1,"") -> -0.0011851264 | D13: =SUMPRODUCT(A13:C13,$I$2:$K$2) -> -0.00046824165
A14: =IFERROR(Merged_data[[#This Row],[BTCUSD_Close]]/Merged_data!D13-1,"") -> 0.149535 | B14: =IFERROR(Merged_data[[#This Row],[XAUUSD_Close]]/Merged_data!C13-1, "") -> -0.024441655 | C14: =IFERROR(Merged_data[[#This Row],[AAPL_Close]]/Merged_data!B13-1,"") -> -0.01202853 | D14: =SUMPRODUCT(A14:C14,$I$2:$K$2) -> 0.031475279 | H14: VaR Using Parametric Method
A15: =IFERROR(Merged_data[[#This Row],[BTCUSD_Close]]/Merged_data!D14-1,"") -> 0.0056112916 | B15: =IFERROR(Merged_data[[#This Row],[XAUUSD_Close]]/Merged_data!C14-1, "") -> -0.0081178375 | C15: =IFERROR(Merged_data[[#This Row],[AAPL_Close]]/Merged_data!B14-1,"") -> 0 | D15: =SUMPRODUCT(A15:C15,$I$2:$K$2) -> -0.0015637475 | H15: Portfolio Mean Return | I15: =I5 -> 0.0015771349 | J15: =I5 -> 0.0015771349
A16: =IFERROR(Merged_data[[#This Row],[BTCUSD_Close]]/Merged_data!D15-1,"") -> 0.012937974 | B16: =IFERROR(Merged_data[[#This Row],[XAUUSD_Close]]/Merged_data!C15-1, "") -> -0.0097526243 | C16: =IFERROR(Merged_data[[#This Row],[AAPL_Close]]/Merged_data!B15-1,"") -> 0.0039690335 | D16: =SUMPRODUCT(A16:C16,$I$2:$K$2) -> 0.0011710524 | H16: Standard Deviation | I16: =I12 -> 0.012683998 | J16: =I12 -> 0.012683998
A17: =IFERROR(Merged_data[[#This Row],[BTCUSD_Close]]/Merged_data!D16-1,"") -> -0.023017182 | B17: =IFERROR(Merged_data[[#This Row],[XAUUSD_Close]]/Merged_data!C16-1, "") -> -0.0030645935 | C17: =IFERROR(Merged_data[[#This Row],[AAPL_Close]]/Merged_data!B16-1,"") -> 0.013767771 | D17: =SUMPRODUCT(A17:C17,$I$2:$K$2) -> -0.0040006607 | H17: Confidence Level | I17: 0.99 | J17: 0.95
A18: =IFERROR(Merged_data[[#This Row],[BTCUSD_Close]]/Merged_data!D17-1,"") -> 0.04063909 | B18: =IFERROR(Merged_data[[#This Row],[XAUUSD_Close]]/Merged_data!C17-1, "") -> -0.0010604082 | C18: =IFERROR(Merged_data[[#This Row],[AAPL_Close]]/Merged_data!B17-1,"") -> -0.014107181 | D18: =SUMPRODUCT(A18:C18,$I$2:$K$2) -> 0.0075354093 | H18: Alpha | I18: 0.01 | J18: 0.05
A19: =IFERROR(Merged_data[[#This Row],[BTCUSD_Close]]/Merged_data!D18-1,"") -> -0.00048311137 | B19: =IFERROR(Merged_data[[#This Row],[XAUUSD_Close]]/Merged_data!C18-1, "") -> 0.019333966 | C19: =IFERROR(Merged_data[[#This Row],[AAPL_Close]]/Merged_data!B18-1,"") -> 0.013423625 | D19: =SUMPRODUCT(A19:C19,$I$2:$K$2) -> 0.01161574 | H19: Z-value | I19: =_xlfn.NORM.S.INV(I18) -> -2.3263479 | J19: =_xlfn.NORM.S.INV(J18) -> -1.6448536
A20: =IFERROR(Merged_data[[#This Row],[BTCUSD_Close]]/Merged_data!D19-1,"") -> 0.0077039255 | B20: =IFERROR(Merged_data[[#This Row],[XAUUSD_Close]]/Merged_data!C19-1, "") -> 0.0078085816 | C20: =IFERROR(Merged_data[[#This Row],[AAPL_Close]]/Merged_data!B19-1,"") -> 0.001137112 | D20: =SUMPRODUCT(A20:C20,$I$2:$K$2) -> 0.0057757439 | H20: Portfolio Value | I20: =Historical!I6 -> 1000000 | J20: =I20 -> 1000000
A21: =IFERROR(Merged_data[[#This Row],[BTCUSD_Close]]/Merged_data!D20-1,"") -> 0.024838458 | B21: =IFERROR(Merged_data[[#This Row],[XAUUSD_Close]]/Merged_data!C20-1, "") -> 0.0068382173 | C21: =IFERROR(Merged_data[[#This Row],[AAPL_Close]]/Merged_data!B20-1,"") -> 0.0031531077 | D21: =SUMPRODUCT(A21:C21,$I$2:$K$2) -> 0.011132757 | H21: 1 Day VaR | I21: =ABS((I15+(I16*I19))*I20) -> 27930.257 | J21: =ABS(J15+(J16*J19))*J20 -> 19286.185
A22: =IFERROR(Merged_data[[#This Row],[BTCUSD_Close]]/Merged_data!D21-1,"") -> 0.044587576 | B22: =IFERROR(Merged_data[[#This Row],[XAUUSD_Close]]/Merged_data!C21-1, "") -> 0.0073200227 | C22: =IFERROR(Merged_data[[#This Row],[AAPL_Close]]/Merged_data!B21-1,"") -> -0.0020940074 | D22: =SUMPRODUCT(A22:C22,$I$2:$K$2) -> 0.01567608
A23: =IFERROR(Merged_data[[#This Row],[BTCUSD_Close]]/Merged_data!D22-1,"") -> 0.0077468502 | B23: =IFERROR(Merged_data[[#This Row],[XAUUSD_Close]]/Merged_data!C22-1, "") -> 0.013591593 | C23: =IFERROR(Merged_data[[#This Row],[AAPL_Close]]/Merged_data!B22-1,"") -> 0.0059096943 | D23: =SUMPRODUCT(A23:C23,$I$2:$K$2) -> 0.0095336005
A24: =IFERROR(Merged_data[[#This Row],[BTCUSD_Close]]/Merged_data!D23-1,"") -> -0.048555494 | B24: =IFERROR(Merged_data[[#This Row],[XAUUSD_Close]]/Merged_data!C23-1, "") -> -0.029830559 | C24: =IFERROR(Merged_data[[#This Row],[AAPL_Close]]/Merged_data!B23-1,"") -> 0.013047758 | D24: =SUMPRODUCT(A24:C24,$I$2:$K$2) -> -0.022584544
A25: =IFERROR(Merged_data[[#This Row],[BTCUSD_Close]]/Merged_data!D24-1,"") -> -0.027746166 | B25: =IFERROR(Merged_data[[#This Row],[XAUUSD_Close]]/Merged_data!C24-1, "") -> 0.0030454474 | C25: =IFERROR(Merged_data[[#This Row],[AAPL_Close]]/Merged_data!B24-1,"") -> 0.0094061406 | D25: =SUMPRODUCT(A25:C25,$I$2:$K$2) -> -0.0042838286
A26: =IFERROR(Merged_data[[#This Row],[BTCUSD_Close]]/Merged_data!D25-1,"") -> 0.047709714 | B26: =IFERROR(Merged_data[[#This Row],[XAUUSD_Close]]/Merged_data!C25-1, "") -> 0.0010329539 | C26: =IFERROR(Merged_data[[#This Row],[AAPL_Close]]/Merged_data!B25-1,"") -> -0.00055365798 | D26: =SUMPRODUCT(A26:C26,$I$2:$K$2) -> 0.014559998
A27: =IFERROR(Merged_data[[#This Row],[BTCUSD_Close]]/Merged_data!D26-1,"") -> 0.012912387 | B27: =IFERROR(Merged_data[[#This Row],[XAUUSD_Close]]/Merged_data!C26-1, "") -> 0.0055046672 | C27: =IFERROR(Merged_data[[#This Row],[AAPL_Close]]/Merged_data!B26-1,"") -> 0.010214256 | D27: =SUMPRODUCT(A27:C27,$I$2:$K$2) -> 0.0091398598
A28: =IFERROR(Merged_data[[#This Row],[BTCUSD_Close]]/Merged_data!D27-1,"") -> -0.020207694 | B28: =IFERROR(Merged_data[[#This Row],[XAUUSD_Close]]/Merged_data!C27-1, "") -> -0.0042992618 | C28: =IFERROR(Merged_data[[#This Row],[AAPL_Close]]/Merged_data!B27-1,"") -> 0.0095246532 | D28: =SUMPRODUCT(A28:C28,$I$2:$K$2) -> -0.0049246171
A29: =IFERROR(Merged_data[[#This Row],[BTCUSD_Close]]/Merged_data!D28-1,"") -> 0.0078076769 | B29: =IFERROR(Merged_data[[#This Row],[XAUUSD_Close]]/Merged_data!C28-1, "") -> 0.0017449395 | C29: =IFERROR(Merged_data[[#This Row],[AAPL_Close]]/Merged_data!B28-1,"") -> 0.012773319 | D29: =SUMPRODUCT(A29:C29,$I$2:$K$2) -> 0.0068722744
A30: =IFERROR(Merged_data[[#This Row],[BTCUSD_Close]]/Merged_data!D29-1,"") -> 0.022484426 | B30: =IFERROR(Merged_data[[#This Row],[XAUUSD_Close]]/Merged_data!C29-1, "") -> 0.0024322295 | C30: =IFERROR(Merged_data[[#This Row],[AAPL_Close]]/Merged_data!B29-1,"") -> 0.0014811209 | D30: =SUMPRODUCT(A30:C30,$I$2:$K$2) -> 0.0081625557
A31: =IFERROR(Merged_data[[#This Row],[BTCUSD_Close]]/Merged_data!D30-1,"") -> -0.016020278 | B31: =IFERROR(Merged_data[[#This Row],[XAUUSD_Close]]/Merged_data!C30-1, "") -> -0.0068337173 | C31: =IFERROR(Merged_data[[#This Row],[AAPL_Close]]/Merged_data!B30-1,"") -> 0.0001235875 | D31: =SUMPRODUCT(A31:C31,$I$2:$K$2) -> -0.0075024941
A32: =IFERROR(Merged_data[[#This Row],[BTCUSD_Close]]/Merged_data!D31-1,"") -> 0.049402561 | B32: =IFERROR(Merged_data[[#This Row],[XAUUSD_Close]]/Merged_data!C31-1, "") -> 0 | C32: =IFERROR(Merged_data[[#This Row],[AAPL_Close]]/Merged_data!B31-1,"") -> -0.00082381484 | D32: =SUMPRODUCT(A32:C32,$I$2:$K$2) -> 0.014573624
A33: =IFERROR(Merged_data[[#This Row],[BTCUSD_Close]]/Merged_data!D32-1,"") -> -0.044561995 | B33: =IFERROR(Merged_data[[#This Row],[XAUUSD_Close]]/Merged_data!C32-1, "") -> 0.010794134 | C33: =IFERROR(Merged_data[[#This Row],[AAPL_Close]]/Merged_data!B32-1,"") -> 0.016102369 | D33: =SUMPRODUCT(A33:C33,$I$2:$K$2) -> -0.0042202338
... A251: =IFERROR(Merged_data[[#This Row],[BTCUSD_Close]]/Merged_data!D250-1,"") -> 0.022008561 | B251: =IFERROR(Merged_data[[#This Row],[XAUUSD_Close]]/Merged_data!C250-1, "") -> 0.0069125548 | C251: =IFERROR(Merged_data[[#This Row],[AAPL_Close]]/Merged_data!B250-1,"") -> 0.004372219 | D251: =SUMPRODUCT(A251:C251,$I$2:$K$2) -> 0.010679256

Sheet Monte_Carlo
A1: BTCUSD_return | B1: XAUSSD_return | C1: AAPL_return | D1: Portfolio_return | E1: Uncorrelated Random Variable | H1: Correlated Random Variable | L1: Simulated Stock Prices | O1: Log Returns | R1: Portfolio ret | S1: Asc Order | T1: Stocks | U1: BTC | V1: Gold | W1: AAPL
E2: w1 | F2: w2 | G2: w3 | H2: w1 | I2: w2 | J2: w3 | L2: BTC | M2: Gold | N2: AAPL | O2: BTC | P2: Gold | Q2: AAPL | T2: Weights | U2: 0.3 | V2: 0.4 | W2: 0.3
A3: =IFERROR(Merged_data[[#This Row],[BTCUSD_Close]]/Merged_data!D2-1,"") -> -0.022252673 | B3: =IFERROR(Merged_data[[#This Row],[XAUUSD_Close]]/Merged_data!C2-1, "") -> 0.002394019 | C3: =IFERROR(Merged_data[[#This Row],[AAPL_Close]]/Merged_data!B2-1,"") -> 0.0036424647 | D3: =SUMPRODUCT(A3:C3,$U$2:$W$2) -> -0.004625455 | E3: =_xlfn.NORM.S.INV(RAND()) -> -0.55641558 | F3: =_xlfn.NORM.S.INV(RAND()) -> 0.2666999 | G3: =_xlfn.NORM.S.INV(RAND()) -> -0.3599675 | H3: {=TRANSPOSE(MMULT(U11:W13,TRANSPOSE(E3:G251)))} -> -0.55641558 | I3: 0.23711829 | J3: -0.49802301 | K3: 1 | L3: =$U$18*EXP(($U$16-(($U$17)^2/2))*K3/249+$U$17*H3) -> 108362.89 | M3: =$V$18*EXP(($V$16-(($V$17)^2/2))*K3/249+$V$17*I3) -> 4132.7801 | N3: =$W$18*EXP(($W$16-(($W$17)^2/2))*K3/249+$W$17*J3) -> 258.6315 | T3: Stock Value | U3: 300000 | V3: 400000 | W3: 300000
A4: =IFERROR(Merged_data[[#This Row],[BTCUSD_Close]]/Merged_data!D3-1,"") -> 0.046813423 | B4: =IFERROR(Merged_data[[#This Row],[XAUUSD_Close]]/Merged_data!C3-1, "") -> -0.00011303411 | C4: =IFERROR(Merged_data[[#This Row],[AAPL_Close]]/Merged_data!B3-1,"") -> 0.0085967207 | D4: =SUMPRODUCT(A4:C4,$U$2:$W$2) -> 0.016577829 | E4: =_xlfn.NORM.S.INV(RAND()) -> -0.14359533 | F4: =_xlfn.NORM.S.INV(RAND()) -> 1.4829434 | G4: =_xlfn.NORM.S.INV(RAND()) -> 0.91432196 | H4: -0.14359533 | I4: 1.4733588 | J4: 0.83618321 | K4: 2 | L4: =$U$18*EXP(($U$16-(($U$17)^2/2))*K4/249+$U$17*H4) -> 109582.26 | M4: =$V$18*EXP(($V$16-(($V$17)^2/2))*K4/249+$V$17*I4) -> 4195.5725 | N4: =$W$18*EXP(($W$16-(($W$17)^2/2))*K4/249+$W$17*J4) -> 265.84165 | O4: =LN(L4/L3) -> 0.011189839 | P4: =LN(M4/M3) -> 0.015079465 | Q4: =LN(N4/N3) -> 0.027496563 | R4: {=_xlfn._xlws.SORT(SUMPRODUCT($U$2:$W$2,O4:Q4))} -> 0.017637707 | S4: {=_xlfn._xlws.SORT(R4:R251)} -> -0.053827014
A5: =IFERROR(Merged_data[[#This Row],[BTCUSD_Close]]/Merged_data!D4-1,"") -> 0.038675266 | B5: =IFERROR(Merged_data[[#This Row],[XAUUSD_Close]]/Merged_data!C4-1, "") -> 0.01183528 | C5: =IFERROR(Merged_data[[#This Row],[AAPL_Close]]/Merged_data!B4-1,"") -> 0.0011593605 | D5: =SUMPRODUCT(A5:C5,$U$2:$W$2) -> 0.0166845 | E5: =_xlfn.NORM.S.INV(RAND()) -> 1.2416172 | F5: =_xlfn.NORM.S.INV(RAND()) -> -0.76004826 | G5: =_xlfn.NORM.S.INV(RAND()) -> -1.7264543 | H5: 1.2416172 | I5: -0.69381071 | J5: -1.3234333 | K5: 3 | L5: =$U$18*EXP(($U$16-(($U$17)^2/2))*K5/249+$U$17*H5) -> 113775.4 | M5: =$V$18*EXP(($V$16-(($V$17)^2/2))*K5/249+$V$17*I5) -> 4086.1131 | N5: =$W$18*EXP(($W$16-(($W$17)^2/2))*K5/249+$W$17*J5) -> 254.26861 | O5: =LN(L5/L4) -> 0.037550824 | P5: =LN(M5/M4) -> -0.026435612 | Q5: =LN(N5/N4) -> -0.044509618 | R5: {=_xlfn._xlws.SORT(SUMPRODUCT($U$2:$W$2,O5:Q5))} -> -0.012661883 | S5: -0.049165114 | T5: Correlation | U5: BTC | V5: Gold | W5: AAPL
A6: =IFERROR(Merged_data[[#This Row],[BTCUSD_Close]]/Merged_data!D5-1,"") -> -0.0033353163 | B6: =IFERROR(Merged_data[[#This Row],[XAUUSD_Close]]/Merged_data!C5-1, "") -> 0.0046527888 | C6: =IFERROR(Merged_data[[#This Row],[AAPL_Close]]/Merged_data!B5-1,"") -> -0.01527726 | D6: =SUMPRODUCT(A6:C6,$U$2:$W$2) -> -0.0037226572 | E6: =_xlfn.NORM.S.INV(RAND()) -> 1.4178785 | F6: =_xlfn.NORM.S.INV(RAND()) -> -2.1206493 | G6: =_xlfn.NORM.S.INV(RAND()) -> -0.69201789 | H6: 1.4178785 | I6: -2.0432808 | J6: -0.27515239 | K6: 4 | L6: =$U$18*EXP(($U$16-(($U$17)^2/2))*K6/249+$U$17*H6) -> 114320.19 | M6: =$V$18*EXP(($V$16-(($V$17)^2/2))*K6/249+$V$17*I6) -> 4019.4012 | N6: =$W$18*EXP(($W$16-(($W$17)^2/2))*K6/249+$W$17*J6) -> 259.82153 | O6: =LN(L6/L5) -> 0.004776863 | P6: =LN(M6/M5) -> -0.016461247 | Q6: =LN(N6/N5) -> 0.021603764 | R6: {=_xlfn._xlws.SORT(SUMPRODUCT($U$2:$W$2,O6:Q6))} -> 0.0013296895 | S6: -0.03819847 | T6: BTC | U6: 1 | V6: =U7 -> 0.052503492 | W6: =U8 -> 0.27058081
A7: =IFERROR(Merged_data[[#This Row],[BTCUSD_Close]]/Merged_data!D6-1,"") -> -0.02767131 | B7: =IFERROR(Merged_data[[#This Row],[XAUUSD_Close]]/Merged_data!C6-1, "") -> -0.014846157 | C7: =IFERROR(Merged_data[[#This Row],[AAPL_Close]]/Merged_data!B6-1,"") -> -0.018210327 | D7: =SUMPRODUCT(A7:C7,$U$2:$W$2) -> -0.019702954 | E7: =_xlfn.NORM.S.INV(RAND()) -> -0.38783667 | F7: =_xlfn.NORM.S.INV(RAND()) -> 0.84566582 | G7: =_xlfn.NORM.S.INV(RAND()) -> -1.9885211 | H7: -0.38783667 | I7: 0.82413665 | J7: -2.0222219 | K7: 5 | L7: =$U$18*EXP(($U$16-(($U$17)^2/2))*K7/249+$U$17*H7) -> 108858.61 | M7: =$V$18*EXP(($V$16-(($V$17)^2/2))*K7/249+$V$17*I7) -> 4162.4741 | N7: =$W$18*EXP(($W$16-(($W$17)^2/2))*K7/249+$W$17*J7) -> 250.63252 | O7: =LN(L7/L6) -> -0.048953354 | P7: =LN(M7/M6) -> 0.034976697 | Q7: =LN(N7/N6) -> -0.036007202 | R7: {=_xlfn._xlws.SORT(SUMPRODUCT($U$2:$W$2,O7:Q7))} -> -0.011497488 | S7: -0.035639034 | T7: Gold | U7: 0.052503492 | V7: 1 | W7: =V8 -> 0.010723509
A8: =IFERROR(Merged_data[[#This Row],[BTCUSD_Close]]/Merged_data!D7-1,"") -> -0.016758109 | B8: =IFERROR(Merged_data[[#This Row],[XAUUSD_Close]]/Merged_data!C7-1, "") -> -0.0035285057 | C8: =IFERROR(Merged_data[[#This Row],[AAPL_Close]]/Merged_data!B7-1,"") -> -0.013282227 | D8: =SUMPRODUCT(A8:C8,$U$2:$W$2) -> -0.010423503 | E8: =_xlfn.NORM.S.INV(RAND()) -> 0.29805953 | F8: =_xlfn.NORM.S.INV(RAND()) -> 0.16743227 | G8: =_xlfn.NORM.S.INV(RAND()) -> 0.96268135 | H8: 0.29805953 | I8: 0.18285051 | J8: 1.0068298 | K8: 6 | L8: =$U$18*EXP(($U$16-(($U$17)^2/2))*K8/249+$U$17*H8) -> 110901.52 | M8: =$V$18*EXP(($V$16-(($V$17)^2/2))*K8/249+$V$17*I8) -> 4130.0391 | N8: =$W$18*EXP(($W$16-(($W$17)^2/2))*K8/249+$W$17*J8) -> 266.77734 | O8: =LN(L8/L7) -> 0.018592768 | P8: =LN(M8/M7) -> -0.0078227602 | Q8: =LN(N8/N7) -> 0.062426598 | R8: {=_xlfn._xlws.SORT(SUMPRODUCT($U$2:$W$2,O8:Q8))} -> 0.021176706 | S8: -0.035391782 | T8: AAPL | U8: 0.27058081 | V8: 0.010723509 | W8: 1
A9: =IFERROR(Merged_data[[#This Row],[BTCUSD_Close]]/Merged_data!D8-1,"") -> -0.018892194 | B9: =IFERROR(Merged_data[[#This Row],[XAUUSD_Close]]/Merged_data!C8-1, "") -> 6.2122809e-05 | C9: =IFERROR(Merged_data[[#This Row],[AAPL_Close]]/Merged_data!B8-1,"") -> -0.0040374067 | D9: =SUMPRODUCT(A9:C9,$U$2:$W$2) -> -0.006854031 | E9: =_xlfn.NORM.S.INV(RAND()) -> -1.4412561 | F9: =_xlfn.NORM.S.INV(RAND()) -> -0.28691843 | G9: =_xlfn.NORM.S.INV(RAND()) -> -0.22142878 | H9: -1.4412561 | I9: -0.36219368 | J9: -0.60214303 | K9: 7 | L9: =$U$18*EXP(($U$16-(($U$17)^2/2))*K9/249+$U$17*H9) -> 105793.53 | M9: =$V$18*EXP(($V$16-(($V$17)^2/2))*K9/249+$V$17*I9) -> 4102.6704 | N9: =$W$18*EXP(($W$16-(($W$17)^2/2))*K9/249+$W$17*J9) -> 258.07579 | O9: =LN(L9/L8) -> -0.047153301 | P9: =LN(M9/M8) -> -0.0066487928 | Q9: =LN(N9/N8) -> -0.033161091 | R9: {=_xlfn._xlws.SORT(SUMPRODUCT($U$2:$W$2,O9:Q9))} -> -0.026753835 | S9: -0.034692048
A10: =IFERROR(Merged_data[[#This Row],[BTCUSD_Close]]/Merged_data!D9-1,"") -> 0.025051042 | B10: =IFERROR(Merged_data[[#This Row],[XAUUSD_Close]]/Merged_data!C9-1, "") -> 0.0026711149 | C10: =IFERROR(Merged_data[[#This Row],[AAPL_Close]]/Merged_data!B9-1,"") -> 0.0064869403 | D10: =SUMPRODUCT(A10:C10,$U$2:$W$2) -> 0.010529841 | E10: =_xlfn.NORM.S.INV(RAND()) -> -0.73494758 | F10: =_xlfn.NORM.S.INV(RAND()) -> 0.92665718 | G10: =_xlfn.NORM.S.INV(RAND()) -> 0.54415683 | H10: -0.73494758 | I10: 0.88679176 | J10: 0.32176021 | K10: 8 | L10: =$U$18*EXP(($U$16-(($U$17)^2/2))*K10/249+$U$17*H10) -> 107838.58 | M10: =$V$18*EXP(($V$16-(($V$17)^2/2))*K10/249+$V$17*I10) -> 4165.6528 | N10: =$W$18*EXP(($W$16-(($W$17)^2/2))*K10/249+$W$17*J10) -> 263.03673 | O10: =LN(L10/L9) -> 0.019146133 | P10: =LN(M10/M9) -> 0.015234929 | Q10: =LN(N10/N9) -> 0.019040395 | R10: {=_xlfn._xlws.SORT(SUMPRODUCT($U$2:$W$2,O10:Q10))} -> 0.01754993 | S10: -0.034683338 | T10: Cholesky | U10: BTC | V10: Gold | W10: AAPL
A11: =IFERROR(Merged_data[[#This Row],[BTCUSD_Close]]/Merged_data!D10-1,"") -> 0.087634007 | B11: =IFERROR(Merged_data[[#This Row],[XAUUSD_Close]]/Merged_data!C10-1, "") -> -0.030954867 | C11: =IFERROR(Merged_data[[#This Row],[AAPL_Close]]/Merged_data!B10-1,"") -> -0.0032651743 | D11: =SUMPRODUCT(A11:C11,$U$2:$W$2) -> 0.012928703 | E11: =_xlfn.NORM.S.INV(RAND()) -> 1.0897017 | F11: =_xlfn.NORM.S.INV(RAND()) -> -2.0455315 | G11: =_xlfn.NORM.S.INV(RAND()) -> 1.9225507 | H11: 1.0897017 | I11: -1.985497 | J11: 2.1528088 | K11: 9 | L11: =$U$18*EXP(($U$16-(($U$17)^2/2))*K11/249+$U$17*H11) -> 113306.8 | M11: =$V$18*EXP(($V$16-(($V$17)^2/2))*K11/249+$V$17*I11) -> 4022.2293 | N11: =$W$18*EXP(($W$16-(($W$17)^2/2))*K11/249+$W$17*J11) -> 273.15242 | O11: =LN(L11/L10) -> 0.049463695 | P11: =LN(M11/M10) -> -0.035036715 | Q11: =LN(N11/N10) -> 0.037736271 | R11: =(SUMPRODUCT($U$2:$W$2,O11:Q11)) -> 0.012145303 | S11: -0.031870884 | T11: BTC | U11: =SQRT(U6) -> 1 | V11: 0 | W11: 0
A12: =IFERROR(Merged_data[[#This Row],[BTCUSD_Close]]/Merged_data!D11-1,"") -> 0.0029609918 | B12: =IFERROR(Merged_data[[#This Row],[XAUUSD_Close]]/Merged_data!C11-1, "") -> 0.017846566 | C12: =IFERROR(Merged_data[[#This Row],[AAPL_Close]]/Merged_data!B11-1,"") -> 0.021369656 | D12: =SUMPRODUCT(A12:C12,$U$2:$W$2) -> 0.014437821 | E12: =_xlfn.NORM.S.INV(RAND()) -> 0.58327717 | F12: =_xlfn.NORM.S.INV(RAND()) -> 1.2223135 | G12: =_xlfn.NORM.S.INV(RAND()) -> -0.96527442 | H12: 0.58327717 | I12: 1.2512517 | J12: -0.77570045 | K12: 10 | L12: =$U$18*EXP(($U$16-(($U$17)^2/2))*K12/249+$U$17*H12) -> 111761.69 | M12: =$V$18*EXP(($V$16-(($V$17)^2/2))*K12/249+$V$17*I12) -> 4184.2109 | N12: =$W$18*EXP(($W$16-(($W$17)^2/2))*K12/249+$W$17*J12) -> 257.15366 | O12: =LN(L12/L11) -> -0.013730347 | P12: =LN(M12/M11) -> 0.03948183 | Q12: =LN(N12/N11) -> -0.060356168 | R12: {=_xlfn._xlws.SORT(SUMPRODUCT($U$2:$W$2,O12:Q12))} -> -0.0064332223 | S12: -0.031594374 | T12: Gold | U12: =U7/U11 -> 0.052503492 | V12: =SQRT(V7-U12^2) -> 0.99862074 | W12: 0
A13: =IFERROR(Merged_data[[#This Row],[BTCUSD_Close]]/Merged_data!D12-1,"") -> 0.010137245 | B13: =IFERROR(Merged_data[[#This Row],[XAUUSD_Close]]/Merged_data!C12-1, "") -> -0.0078846928 | C13: =IFERROR(Merged_data[[#This Row],[AAPL_Close]]/Merged_data!B12-1,"") -> -0.0011851264 | D13: =SUMPRODUCT(A13:C13,$U$2:$W$2) -> -0.00046824165 | E13: =_xlfn.NORM.S.INV(RAND()) -> -5.4942116e-05 | F13: =_xlfn.NORM.S.INV(RAND()) -> -0.93622046 | G13: =_xlfn.NORM.S.INV(RAND()) -> -1.3335499 | H13: -5.4942116e-05 | I13: -0.93493206 | J13: -1.280546 | K13: 11 | L13: =$U$18*EXP(($U$16-(($U$17)^2/2))*K13/249+$U$17*H13) -> 110008.05 | M13: =$V$18*EXP(($V$16-(($V$17)^2/2))*K13/249+$V$17*I13) -> 4074.1029 | N13: =$W$18*EXP(($W$16-(($W$17)^2/2))*K13/249+$W$17*J13) -> 254.49172 | O13: =LN(L13/L12) -> -0.015815267 | P13: =LN(M13/M12) -> -0.026667549 | Q13: =LN(N13/N12) -> -0.010405503 | R13: {=_xlfn._xlws.SORT(SUMPRODUCT($U$2:$W$2,O13:Q13))} -> -0.018533251 | S13: -0.030872912 | T13: AAPL | U13: =U8/U11 -> 0.27058081 | V13: =((W7-U13*U12)/V12) -> -0.0034877382 | W13: =SQRT(W8-U13^2-V13^2) -> 0.96269095
A14: =IFERROR(Merged_data[[#This Row],[BTCUSD_Close]]/Merged_data!D13-1,"") -> 0.149535 | B14: =IFERROR(Merged_data[[#This Row],[XAUUSD_Close]]/Merged_data!C13-1, "") -> -0.024441655 | C14: =IFERROR(Merged_data[[#This Row],[AAPL_Close]]/Merged_data!B13-1,"") -> -0.01202853 | D14: =SUMPRODUCT(A14:C14,$U$2:$W$2) -> 0.031475279 | E14: =_xlfn.NORM.S.INV(RAND()) -> -1.0985567 | F14: =_xlfn.NORM.S.INV(RAND()) -> -0.13192363 | G14: =_xlfn.NORM.S.INV(RAND()) -> 1.6993731 | H14: -1.0985567 | I14: -0.18941974 | J14: 1.3391828 | K14: 12 | L14: =$U$18*EXP(($U$16-(($U$17)^2/2))*K14/249+$U$17*H14) -> 106780.18 | M14: =$V$18*EXP(($V$16-(($V$17)^2/2))*K14/249+$V$17*I14) -> 4111.3198 | N14: =$W$18*EXP(($W$16-(($W$17)^2/2))*K14/249+$W$17*J14) -> 268.60957 | O14: =LN(L14/L13) -> -0.029781213 | P14: =LN(M14/M13) -> 0.0090935222 | Q14: =LN(N14/N13) -> 0.053990631 | R14: {=_xlfn._xlws.SORT(SUMPRODUCT($U$2:$W$2,O14:Q14))} -> 0.010900234 | S14: -0.030110754
A15: =IFERROR(Merged_data[[#This Row],[BTCUSD_Close]]/Merged_data!D14-1,"") -> 0.0056112916 | B15: =IFERROR(Merged_data[[#This Row],[XAUUSD_Close]]/Merged_data!C14-1, "") -> -0.0081178375 | C15: =IFERROR(Merged_data[[#This Row],[AAPL_Close]]/Merged_data!B14-1,"") -> 0 | D15: =SUMPRODUCT(A15:C15,$U$2:$W$2) -> -0.0015637475 | E15: =_xlfn.NORM.S.INV(RAND()) -> 0.21251299 | F15: =_xlfn.NORM.S.INV(RAND()) -> -0.076209794 | G15: =_xlfn.NORM.S.INV(RAND()) -> -0.77464468 | H15: 0.21251299 | I15: -0.064947007 | J15: -0.68797569 | K15: 13 | L15: =$U$18*EXP(($U$16-(($U$17)^2/2))*K15/249+$U$17*H15) -> 110643.49 | M15: =$V$18*EXP(($V$16-(($V$17)^2/2))*K15/249+$V$17*I15) -> 4117.5656 | N15: =$W$18*EXP(($W$16-(($W$17)^2/2))*K15/249+$W$17*J15) -> 257.61834 | O15: =LN(L15/L14) -> 0.035540854 | P15: =LN(M15/M14) -> 0.0015180299 | Q15: =LN(N15/N14) -> -0.041779717 | R15: {=_xlfn._xlws.SORT(SUMPRODUCT($U$2:$W$2,O15:Q15))} -> -0.0012644471 | S15: -0.029217835 | T15: Risk free rate | U15: BTC | V15: Gold | W15: AAPL
A16: =IFERROR(Merged_data[[#This Row],[BTCUSD_Close]]/Merged_data!D15-1,"") -> 0.012937974 | B16: =IFERROR(Merged_data[[#This Row],[XAUUSD_Close]]/Merged_data!C15-1, "") -> -0.0097526243 | C16: =IFERROR(Merged_data[[#This Row],[AAPL_Close]]/Merged_data!B15-1,"") -> 0.0039690335 | D16: =SUMPRODUCT(A16:C16,$U$2:$W$2) -> 0.0011710524 | E16: =_xlfn.NORM.S.INV(RAND()) -> 0.080867384 | F16: =_xlfn.NORM.S.INV(RAND()) -> -0.99599114 | G16: =_xlfn.NORM.S.INV(RAND()) -> 0.4274313 | H16: 0.080867384 | I16: -0.99037159 | J16: 0.43683916 | K16: 14 | L16: =$U$18*EXP(($U$16-(($U$17)^2/2))*K16/249+$U$17*H16) -> 110249.16 | M16: =$V$18*EXP(($V$16-(($V$17)^2/2))*K16/249+$V$17*I16) -> 4071.345 | N16: =$W$18*EXP(($W$16-(($W$17)^2/2))*K16/249+$W$17*J16) -> 263.65997 | O16: =LN(L16/L15) -> -0.0035703108 | P16: =LN(M16/M15) -> -0.011288704 | Q16: =LN(N16/N15) -> 0.023181097 | R16: {=_xlfn._xlws.SORT(SUMPRODUCT($U$2:$W$2,O16:Q16))} -> 0.001367754 | S16: -0.028666857 | T16: Drift | U16: 0 | V16: =U16 -> 0 | W16: =V16 -> 0
A17: =IFERROR(Merged_data[[#This Row],[BTCUSD_Close]]/Merged_data!D16-1,"") -> -0.023017182 | B17: =IFERROR(Merged_data[[#This Row],[XAUUSD_Close]]/Merged_data!C16-1, "") -> -0.0030645935 | C17: =IFERROR(Merged_data[[#This Row],[AAPL_Close]]/Merged_data!B16-1,"") -> 0.013767771 | D17: =SUMPRODUCT(A17:C17,$U$2:$W$2) -> -0.0040006607 | E17: =_xlfn.NORM.S.INV(RAND()) -> 0.10804295 | F17: =_xlfn.NORM.S.INV(RAND()) -> 0.45342756 | G17: =_xlfn.NORM.S.INV(RAND()) -> 0.14899342 | H17: 0.10804295 | I17: 0.4584748 | J17: 0.17108753 | K17: 15 | L17: =$U$18*EXP(($U$16-(($U$17)^2/2))*K17/249+$U$17*H17) -> 110330.25 | M17: =$V$18*EXP(($V$16-(($V$17)^2/2))*K17/249+$V$17*I17) -> 4143.9369 | N17: =$W$18*EXP(($W$16-(($W$17)^2/2))*K17/249+$W$17*J17) -> 262.21963 | O17: =LN(L17/L16) -> 0.00073523798 | P17: =LN(M17/M16) -> 0.017672849 | Q17: =LN(N17/N16) -> -0.0054778796 | R17: {=_xlfn._xlws.SORT(SUMPRODUCT($U$2:$W$2,O17:Q17))} -> 0.0056463473 | S17: -0.028358743 | T17: Volatility | U17: =_xlfn.STDEV.S(A3:A251) -> 0.027109413 | V17: =_xlfn.STDEV.S(B3:B251) -> 0.012198083 | W17: =_xlfn.STDEV.S(C3:C251) -> 0.020609569
A18: =IFERROR(Merged_data[[#This Row],[BTCUSD_Close]]/Merged_data!D17-1,"") -> 0.04063909 | B18: =IFERROR(Merged_data[[#This Row],[XAUUSD_Close]]/Merged_data!C17-1, "") -> -0.0010604082 | C18: =IFERROR(Merged_data[[#This Row],[AAPL_Close]]/Merged_data!B17-1,"") -> -0.014107181 | D18: =SUMPRODUCT(A18:C18,$U$2:$W$2) -> 0.0075354093 | E18: =_xlfn.NORM.S.INV(RAND()) -> 1.2250074 | F18: =_xlfn.NORM.S.INV(RAND()) -> -1.3669451 | G18: =_xlfn.NORM.S.INV(RAND()) -> 0.53073558 | H18: 1.2250074 | I18: -1.3007425 | J18: 0.84716538 | K18: 16 | L18: =$U$18*EXP(($U$16-(($U$17)^2/2))*K18/249+$U$17*H18) -> 113722 | M18: =$V$18*EXP(($V$16-(($V$17)^2/2))*K18/249+$V$17*I18) -> 4055.9579 | N18: =$W$18*EXP(($W$16-(($W$17)^2/2))*K18/249+$W$17*J18) -> 265.89865 | O18: =LN(L18/L17) -> 0.030278775 | P18: =LN(M18/M17) -> -0.021459378 | Q18: =LN(N18/N17) -> 0.01393282 | R18: {=_xlfn._xlws.SORT(SUMPRODUCT($U$2:$W$2,O18:Q18))} -> 0.0046797276 | S18: -0.02769033 | T18: S0 | U18: =Merged_data!D252 -> 110010 | V18: =Merged_data!C252 -> 4120.845 | W18: =Merged_data!B252 -> 261.3
A19: =IFERROR(Merged_data[[#This Row],[BTCUSD_Close]]/Merged_data!D18-1,"") -> -0.00048311137 | B19: =IFERROR(Merged_data[[#This Row],[XAUUSD_Close]]/Merged_data!C18-1, "") -> 0.019333966 | C19: =IFERROR(Merged_data[[#This Row],[AAPL_Close]]/Merged_data!B18-1,"") -> 0.013423625 | D19: =SUMPRODUCT(A19:C19,$U$2:$W$2) -> 0.01161574 | E19: =_xlfn.NORM.S.INV(RAND()) -> -0.023465397 | F19: =_xlfn.NORM.S.INV(RAND()) -> 0.72337944 | G19: =_xlfn.NORM.S.INV(RAND()) -> 0.97960062 | H19: -0.023465397 | I19: 0.72114969 | J19: 0.9341804 | K19: 17 | L19: =$U$18*EXP(($U$16-(($U$17)^2/2))*K19/249+$U$17*H19) -> 109937.28 | M19: =$V$18*EXP(($V$16-(($V$17)^2/2))*K19/249+$V$17*I19) -> 4157.2334 | N19: =$W$18*EXP(($W$16-(($W$17)^2/2))*K19/249+$W$17*J19) -> 266.3757 | O19: =LN(L19/L18) -> -0.033846841 | P19: =LN(M19/M18) -> 0.02466291 | Q19: =LN(N19/N18) -> 0.0017924893 | R19: {=_xlfn._xlws.SORT(SUMPRODUCT($U$2:$W$2,O19:Q19))} -> 0.00024885864 | S19: -0.027241067
A20: =IFERROR(Merged_data[[#This Row],[BTCUSD_Close]]/Merged_data!D19-1,"") -> 0.0077039255 | B20: =IFERROR(Merged_data[[#This Row],[XAUUSD_Close]]/Merged_data!C19-1, "") -> 0.0078085816 | C20: =IFERROR(Merged_data[[#This Row],[AAPL_Close]]/Merged_data!B19-1,"") -> 0.001137112 | D20: =SUMPRODUCT(A20:C20,$U$2:$W$2) -> 0.0057757439 | E20: =_xlfn.NORM.S.INV(RAND()) -> 1.4330019 | F20: =_xlfn.NORM.S.INV(RAND()) -> 0.14243417 | G20: =_xlfn.NORM.S.INV(RAND()) -> 0.91706999 | H20: 1.4330019 | I20: 0.21747532 | J20: 1.270101 | K20: 18 | L20: =$U$18*EXP(($U$16-(($U$17)^2/2))*K20/249+$U$17*H20) -> 114364.71 | M20: =$V$18*EXP(($V$16-(($V$17)^2/2))*K20/249+$V$17*I20) -> 4131.769 | N20: =$W$18*EXP(($W$16-(($W$17)^2/2))*K20/249+$W$17*J20) -> 268.22604 | O20: =LN(L20/L19) -> 0.039482499 | P20: =LN(M20/M19) -> -0.0061441605 | Q20: =LN(N20/N19) -> 0.0069223265 | R20: {=_xlfn._xlws.SORT(SUMPRODUCT($U$2:$W$2,O20:Q20))} -> 0.011463783 | S20: -0.027004467 | T20: VaR Using Monte Carlo
A21: =IFERROR(Merged_data[[#This Row],[BTCUSD_Close]]/Merged_data!D20-1,"") -> 0.024838458 | B21: =IFERROR(Merged_data[[#This Row],[XAUUSD_Close]]/Merged_data!C20-1, "") -> 0.0068382173 | C21: =IFERROR(Merged_data[[#This Row],[AAPL_Close]]/Merged_data!B20-1,"") -> 0.0031531077 | D21: =SUMPRODUCT(A21:C21,$U$2:$W$2) -> 0.011132757 | E21: =_xlfn.NORM.S.INV(RAND()) -> 1.9031164 | F21: =_xlfn.NORM.S.INV(RAND()) -> 0.77312682 | G21: =_xlfn.NORM.S.INV(RAND()) -> 1.3173671 | H21: 1.9031164 | I21: 0.87198073 | J21: 1.7804677 | K21: 19 | L21: =$U$18*EXP(($U$16-(($U$17)^2/2))*K21/249+$U$17*H21) -> 115831.39 | M21: =$V$18*EXP(($V$16-(($V$17)^2/2))*K21/249+$V$17*I21) -> 4164.8866 | N21: =$W$18*EXP(($W$16-(($W$17)^2/2))*K21/249+$W$17*J21) -> 271.06202 | O21: =LN(L21/L20) -> 0.012743052 | P21: =LN(M21/M20) -> 0.0079834124 | Q21: =LN(N21/N20) -> 0.010517585 | R21: {=_xlfn._xlws.SORT(SUMPRODUCT($U$2:$W$2,O21:Q21))} -> 0.010171556 | S21: -0.026753835 | T21: No. of returns | U21: =COUNT(_xlfn.ANCHORARRAY(S4)) -> 248 | V21: =U21 -> 248
A22: =IFERROR(Merged_data[[#This Row],[BTCUSD_Close]]/Merged_data!D21-1,"") -> 0.044587576 | B22: =IFERROR(Merged_data[[#This Row],[XAUUSD_Close]]/Merged_data!C21-1, "") -> 0.0073200227 | C22: =IFERROR(Merged_data[[#This Row],[AAPL_Close]]/Merged_data!B21-1,"") -> -0.0020940074 | D22: =SUMPRODUCT(A22:C22,$U$2:$W$2) -> 0.01567608 | E22: =_xlfn.NORM.S.INV(RAND()) -> -0.77689601 | F22: =_xlfn.NORM.S.INV(RAND()) -> 0.38926291 | G22: =_xlfn.NORM.S.INV(RAND()) -> 0.17326481 | H22: -0.77689601 | I22: 0.34793627 | J22: -0.044770332 | K22: 20 | L22: =$U$18*EXP(($U$16-(($U$17)^2/2))*K22/249+$U$17*H22) -> 107714.11 | M22: =$V$18*EXP(($V$16-(($V$17)^2/2))*K22/249+$V$17*I22) -> 4138.3469 | N22: =$W$18*EXP(($W$16-(($W$17)^2/2))*K22/249+$W$17*J22) -> 261.05456 | O22: =LN(L22/L21) -> -0.07265504 | P22: =LN(M22/M21) -> -0.0063926365 | Q22: =LN(N22/N21) -> -0.037618223 | R22: {=_xlfn._xlws.SORT(SUMPRODUCT($U$2:$W$2,O22:Q22))} -> -0.035639034 | S22: -0.025561276 | T22: C L | U22: 0.99 | V22: 0.95
A23: =IFERROR(Merged_data[[#This Row],[BTCUSD_Close]]/Merged_data!D22-1,"") -> 0.0077468502 | B23: =IFERROR(Merged_data[[#This Row],[XAUUSD_Close]]/Merged_data!C22-1, "") -> 0.013591593 | C23: =IFERROR(Merged_data[[#This Row],[AAPL_Close]]/Merged_data!B22-1,"") -> 0.0059096943 | D23: =SUMPRODUCT(A23:C23,$U$2:$W$2) -> 0.0095336005 | E23: =_xlfn.NORM.S.INV(RAND()) -> 0.38462622 | F23: =_xlfn.NORM.S.INV(RAND()) -> 0.60956034 | G23: =_xlfn.NORM.S.INV(RAND()) -> -0.83049908 | H23: 0.38462622 | I23: 0.62891382 | J23: -0.69756746 | K23: 21 | L23: =$U$18*EXP(($U$16-(($U$17)^2/2))*K23/249+$U$17*H23) -> 111159.63 | M23: =$V$18*EXP(($V$16-(($V$17)^2/2))*K23/249+$V$17*I23) -> 4152.5538 | N23: =$W$18*EXP(($W$16-(($W$17)^2/2))*K23/249+$W$17*J23) -> 257.56566 | O23: =LN(L23/L22) -> 0.03148671 | P23: =LN(M23/M22) -> 0.0034270886 | Q23: =LN(N23/N22) -> -0.013454721 | R23: {=_xlfn._xlws.SORT(SUMPRODUCT($U$2:$W$2,O23:Q23))} -> 0.0067804323 | S23: -0.023807558 | T23: Alpha | U23: 0.01 | V23: 0.05
A24: =IFERROR(Merged_data[[#This Row],[BTCUSD_Close]]/Merged_data!D23-1,"") -> -0.048555494 | B24: =IFERROR(Merged_data[[#This Row],[XAUUSD_Close]]/Merged_data!C23-1, "") -> -0.029830559 | C24: =IFERROR(Merged_data[[#This Row],[AAPL_Close]]/Merged_data!B23-1,"") -> 0.013047758 | D24: =SUMPRODUCT(A24:C24,$U$2:$W$2) -> -0.022584544 | E24: =_xlfn.NORM.S.INV(RAND()) -> -0.98196429 | F24: =_xlfn.NORM.S.INV(RAND()) -> -0.45707703 | G24: =_xlfn.NORM.S.INV(RAND()) -> -0.62717625 | H24: -0.98196429 | I24: -0.50800315 | J24: -0.86788342 | K24: 22 | L24: =$U$18*EXP(($U$16-(($U$17)^2/2))*K24/249+$U$17*H24) -> 107116.64 | M24: =$V$18*EXP(($V$16-(($V$17)^2/2))*K24/249+$V$17*I24) -> 4095.3615 | N24: =$W$18*EXP(($W$16-(($W$17)^2/2))*K24/249+$W$17*J24) -> 256.66294 | O24: =LN(L24/L23) -> -0.037048943 | P24: =LN(M24/M23) -> -0.013868506 | Q24: =LN(N24/N23) -> -0.0035109915 | R24: {=_xlfn._xlws.SORT(SUMPRODUCT($U$2:$W$2,O24:Q24))} -> -0.017715383 | S24: -0.023750573 | T24: Ret. at pos. | U24: =_xlfn.PERCENTILE.INC(S4:S251,0.01) -> -0.036995535 | V24: =_xlfn.PERCENTILE.INC(S4:S251,0.05) -> -0.028559017
A25: =IFERROR(Merged_data[[#This Row],[BTCUSD_Close]]/Merged_data!D24-1,"") -> -0.027746166 | B25: =IFERROR(Merged_data[[#This Row],[XAUUSD_Close]]/Merged_data!C24-1, "") -> 0.0030454474 | C25: =IFERROR(Merged_data[[#This Row],[AAPL_Close]]/Merged_data!B24-1,"") -> 0.0094061406 | D25: =SUMPRODUCT(A25:C25,$U$2:$W$2) -> -0.0042838286 | E25: =_xlfn.NORM.S.INV(RAND()) -> 0.63164353 | F25: =_xlfn.NORM.S.INV(RAND()) -> -0.5986755 | G25: =_xlfn.NORM.S.INV(RAND()) -> 1.9864049 | H25: 0.63164353 | I25: -0.56468628 | J25: 2.0852927 | K25: 23 | L25: =$U$18*EXP(($U$16-(($U$17)^2/2))*K25/249+$U$17*H25) -> 111906.18 | M25: =$V$18*EXP(($V$16-(($V$17)^2/2))*K25/249+$V$17*I25) -> 4092.5297 | N25: =$W$18*EXP(($W$16-(($W$17)^2/2))*K25/249+$W$17*J25) -> 272.76934 | O25: =LN(L25/L24) -> 0.043742485 | P25: =LN(M25/M24) -> -0.00069172431 | Q25: =LN(N25/N24) -> 0.060862834 | R25: {=_xlfn._xlws.SORT(SUMPRODUCT($U$2:$W$2,O25:Q25))} -> 0.031104906 | S25: -0.023083403 | T25: Portfolio value | U25: =Historical!I15 -> 1000000 | V25: =U25 -> 1000000
A26: =IFERROR(Merged_data[[#This Row],[BTCUSD_Close]]/Merged_data!D25-1,"") -> 0.047709714 | B26: =IFERROR(Merged_data[[#This Row],[XAUUSD_Close]]/Merged_data!C25-1, "") -> 0.0010329539 | C26: =IFERROR(Merged_data[[#This Row],[AAPL_Close]]/Merged_data!B25-1,"") -> -0.00055365798 | D26: =SUMPRODUCT(A26:C26,$U$2:$W$2) -> 0.014559998 | E26: =_xlfn.NORM.S.INV(RAND()) -> 1.1364643 | F26: =_xlfn.NORM.S.INV(RAND()) -> -0.011030797 | G26: =_xlfn.NORM.S.INV(RAND()) -> 0.07435377 | H26: 1.1364643 | I26: 0.048652759 | J26: 0.37912359 | K26: 24 | L26: =$U$18*EXP(($U$16-(($U$17)^2/2))*K26/249+$U$17*H26) -> 113448.02 | M26: =$V$18*EXP(($V$16-(($V$17)^2/2))*K26/249+$V$17*I26) -> 4123.2618 | N26: =$W$18*EXP(($W$16-(($W$17)^2/2))*K26/249+$W$17*J26) -> 263.34429 | O26: =LN(L26/L25) -> 0.013683918 | P26: =LN(M26/M25) -> 0.0074812616 | Q26: =LN(N26/N25) -> -0.035164262 | R26: {=_xlfn._xlws.SORT(SUMPRODUCT($U$2:$W$2,O26:Q26))} -> -0.0034515987 | S26: -0.022413142 | T26: 1 Day Var | U26: =ABS(U25*U24) -> 36995.535 | V26: =ABS(V25*V24) -> 28559.017
A27: =IFERROR(Merged_data[[#This Row],[BTCUSD_Close]]/Merged_data!D26-1,"") -> 0.012912387 | B27: =IFERROR(Merged_data[[#This Row],[XAUUSD_Close]]/Merged_data!C26-1, "") -> 0.0055046672 | C27: =IFERROR(Merged_data[[#This Row],[AAPL_Close]]/Merged_data!B26-1,"") -> 0.010214256 | D27: =SUMPRODUCT(A27:C27,$U$2:$W$2) -> 0.0091398598 | E27: =_xlfn.NORM.S.INV(RAND()) -> 0.7294416 | F27: =_xlfn.NORM.S.INV(RAND()) -> -0.7153974 | G27: =_xlfn.NORM.S.INV(RAND()) -> 0.86955426 | H27: 0.7294416 | I27: -0.67611245 | J27: 1.03698 | K27: 25 | L27: =$U$18*EXP(($U$16-(($U$17)^2/2))*K27/249+$U$17*H27) -> 112202.93 | M27: =$V$18*EXP(($V$16-(($V$17)^2/2))*K27/249+$V$17*I27) -> 4086.9685 | N27: =$W$18*EXP(($W$16-(($W$17)^2/2))*K27/249+$W$17*J27) -> 266.93884 | O27: =LN(L27/L26) -> -0.011035621 | P27: =LN(M27/M26) -> -0.0088410448 | Q27: =LN(N27/N26) -> 0.013557285 | R27: {=_xlfn._xlws.SORT(SUMPRODUCT($U$2:$W$2,O27:Q27))} -> -0.0027799188 | S27: -0.022267001
A28: =IFERROR(Merged_data[[#This Row],[BTCUSD_Close]]/Merged_data!D27-1,"") -> -0.020207694 | B28: =IFERROR(Merged_data[[#This Row],[XAUUSD_Close]]/Merged_data!C27-1, "") -> -0.0042992618 | C28: =IFERROR(Merged_data[[#This Row],[AAPL_Close]]/Merged_data!B27-1,"") -> 0.0095246532 | D28: =SUMPRODUCT(A28:C28,$U$2:$W$2) -> -0.0049246171 | E28: =_xlfn.NORM.S.INV(RAND()) -> 0.64824305 | F28: =_xlfn.NORM.S.INV(RAND()) -> -0.36071536 | G28: =_xlfn.NORM.S.INV(RAND()) -> -0.35033038 | H28: 0.64824305 | I28: -0.32618282 | J28: -0.16059968 | K28: 26 | L28: =$U$18*EXP(($U$16-(($U$17)^2/2))*K28/249+$U$17*H28) -> 111956.05 | M28: =$V$18*EXP(($V$16-(($V$17)^2/2))*K28/249+$V$17*I28) -> 4104.4497 | N28: =$W$18*EXP(($W$16-(($W$17)^2/2))*K28/249+$W$17*J28) -> 260.43078 | O28: =LN(L28/L27) -> -0.0022027207 | P28: =LN(M28/M27) -> 0.0042681718 | Q28: =LN(N28/N27) -> -0.024682455 | R28: {=_xlfn._xlws.SORT(SUMPRODUCT($U$2:$W$2,O28:Q28))} -> -0.006358284 | S28: -0.022126513
A29: =IFERROR(Merged_data[[#This Row],[BTCUSD_Close]]/Merged_data!D28-1,"") -> 0.0078076769 | B29: =IFERROR(Merged_data[[#This Row],[XAUUSD_Close]]/Merged_data!C28-1, "") -> 0.0017449395 | C29: =IFERROR(Merged_data[[#This Row],[AAPL_Close]]/Merged_data!B28-1,"") -> 0.012773319 | D29: =SUMPRODUCT(A29:C29,$U$2:$W$2) -> 0.0068722744 | E29: =_xlfn.NORM.S.INV(RAND()) -> 0.4198387 | F29: =_xlfn.NORM.S.INV(RAND()) -> -1.1210964 | G29: =_xlfn.NORM.S.INV(RAND()) -> -1.7239742 | H29: 0.4198387 | I29: -1.0975071 | J29: -1.542144 | K29: 27 | L29: =$U$18*EXP(($U$16-(($U$17)^2/2))*K29/249+$U$17*H29) -> 111264.81 | M29: =$V$18*EXP(($V$16-(($V$17)^2/2))*K29/249+$V$17*I29) -> 4066.0121 | N29: =$W$18*EXP(($W$16-(($W$17)^2/2))*K29/249+$W$17*J29) -> 253.11988 | O29: =LN(L29/L28) -> -0.0061933837 | P29: =LN(M29/M28) -> -0.0094089766 | Q29: =LN(N29/N28) -> -0.028473886 | R29: {=_xlfn._xlws.SORT(SUMPRODUCT($U$2:$W$2,O29:Q29))} -> -0.014163772 | S29: -0.021924296
A30: =IFERROR(Merged_data[[#This Row],[BTCUSD_Close]]/Merged_data!D29-1,"") -> 0.022484426 | B30: =IFERROR(Merged_data[[#This Row],[XAUUSD_Close]]/Merged_data!C29-1, "") -> 0.0024322295 | C30: =IFERROR(Merged_data[[#This Row],[AAPL_Close]]/Merged_data!B29-1,"") -> 0.0014811209 | D30: =SUMPRODUCT(A30:C30,$U$2:$W$2) -> 0.0081625557 | E30: =_xlfn.NORM.S.INV(RAND()) -> -0.73371935 | F30: =_xlfn.NORM.S.INV(RAND()) -> 0.13638708 | G30: =_xlfn.NORM.S.INV(RAND()) -> -1.2076077 | H30: -0.73371935 | I30: 0.097676139 | J30: -1.3615591 | K30: 28 | L30: =$U$18*EXP(($U$16-(($U$17)^2/2))*K30/249+$U$17*H30) -> 107838.99 | M30: =$V$18*EXP(($V$16-(($V$17)^2/2))*K30/249+$V$17*I30) -> 4125.7232 | N30: =$W$18*EXP(($W$16-(($W$17)^2/2))*K30/249+$W$17*J30) -> 254.06348 | O30: =LN(L30/L29) -> -0.031273757 | P30: =LN(M30/M29) -> 0.014578646 | Q30: =LN(N30/N29) -> 0.0037209242 | R30: {=_xlfn._xlws.SORT(SUMPRODUCT($U$2:$W$2,O30:Q30))} -> -0.0024343916 | S30: -0.021444529
A31: =IFERROR(Merged_data[[#This Row],[BTCUSD_Close]]/Merged_data!D30-1,"") -> -0.016020278 | B31: =IFERROR(Merged_data[[#This Row],[XAUUSD_Close]]/Merged_data!C30-1, "") -> -0.0068337173 | C31: =IFERROR(Merged_data[[#This Row],[AAPL_Close]]/Merged_data!B30-1,"") -> 0.0001235875 | D31: =SUMPRODUCT(A31:C31,$U$2:$W$2) -> -0.0075024941 | E31: =_xlfn.NORM.S.INV(RAND()) -> 1.6329967 | F31: =_xlfn.NORM.S.INV(RAND()) -> -0.75436517 | G31: =_xlfn.NORM.S.INV(RAND()) -> 0.81033478 | H31: 1.6329967 | I31: -0.66758668 | J31: 1.2245906 | K31: 29 | L31: =$U$18*EXP(($U$16-(($U$17)^2/2))*K31/249+$U$17*H31) -> 114984.58 | M31: =$V$18*EXP(($V$16-(($V$17)^2/2))*K31/249+$V$17*I31) -> 4087.3887 | N31: =$W$18*EXP(($W$16-(($W$17)^2/2))*K31/249+$W$17*J31) -> 267.97206 | O31: =LN(L31/L30) -> 0.064158808 | P31: =LN(M31/M30) -> -0.0093350379 | Q31: =LN(N31/N30) -> 0.053298577 | R31: {=_xlfn._xlws.SORT(SUMPRODUCT($U$2:$W$2,O31:Q31))} -> 0.0315032 | S31: -0.021308397
A32: =IFERROR(Merged_data[[#This Row],[BTCUSD_Close]]/Merged_data!D31-1,"") -> 0.049402561 | B32: =IFERROR(Merged_data[[#This Row],[XAUUSD_Close]]/Merged_data!C31-1, "") -> 0 | C32: =IFERROR(Merged_data[[#This Row],[AAPL_Close]]/Merged_data!B31-1,"") -> -0.00082381484 | D32: =SUMPRODUCT(A32:C32,$U$2:$W$2) -> 0.014573624 | E32: =_xlfn.NORM.S.INV(RAND()) -> -0.41104744 | F32: =_xlfn.NORM.S.INV(RAND()) -> -0.30819002 | G32: =_xlfn.NORM.S.INV(RAND()) -> -1.9262183 | H32: -0.41104744 | I32: -0.32934637 | J32: -1.9644996 | K32: 30 | L32: =$U$18*EXP(($U$16-(($U$17)^2/2))*K32/249+$U$17*H32) -> 108786.12 | M32: =$V$18*EXP(($V$16-(($V$17)^2/2))*K32/249+$V$17*I32) -> 4104.2864 | N32: =$W$18*EXP(($W$16-(($W$17)^2/2))*K32/249+$W$17*J32) -> 250.9255 | O32: =LN(L32/L31) -> -0.055414314 | P32: =LN(M32/M31) -> 0.0041255844 | Q32: =LN(N32/N31) -> -0.065726627 | R32: {=_xlfn._xlws.SORT(SUMPRODUCT($U$2:$W$2,O32:Q32))} -> -0.034692048 | S32: -0.021069713
